Workbook

Sheet Legend
A1: The Matrx Alchemizr — Act III Tag Assignment
A2: Tags drive the falling-tag rain field and the GO match query in the Vibes & Scribes module.
A5: HOW TO USE THIS WORKBOOK
A6: Track Tags | B6: One row per Act III track. The five yellow tag columns are the editable cells — everything else is reference or formula.
A7: Tag Dictionary | B7: The closed vocabulary. Only labels listed there may be typed into Track Tags; anything else is rejected by the database seed.
A8: Source Reconciliation | B8: Which source each track was tagged from, and why one supplied workbook was set aside.
A9: Coverage QA | B9: Live counts. Every figure recalculates from Track Tags.
A11: EDITING RULES
A12: Format | B12: Comma-separated labels, e.g. Dark, Gritty, Empowering. Spelling and capitalisation must match the Tag Dictionary exactly — the match query compares literal strings.
A13: Example row | B13: See row 2 of Track Tags (Welcome To The Fire) for the expected format.
A14: Categories | B14: A label belongs to exactly one category. Scoring is per category, so putting Fire in the Theme column would never match a track tagged Fire under Element.
A15: After editing | B15: Re-generate supabase/migrations/20260814010000_seed_act_three_alchemizr_tags.sql so the database matches this sheet. The sheet is the source of truth, the migration is the copy.
A17: SOURCES USED
A18: Primary | B18: ActThreeReclamationLyrics.docx — the master lyric book. 32 tracks, whose order and titles match the live public.tracks roster exactly.
A19: Corroborating | B19: act.three.tracks_updated_media_lyrics_UPDATED.xlsx, sheet "Updated Track Order" — joined to tracks BY TITLE, never by row position. Covers 21 of the 32 tracks.
A20: Author-supplied | B20: Body Jumper lyrics, supplied directly by the author. The master lyric book carries only the line "Lyrics not present in the supplied master sources" under that title.
A21: Set aside | B21: act.three.tracks_updated_media_lyrics_CORRECTED2.xlsm — its taxonomy columns are misaligned against its own track names. See the Source Reconciliation sheet.
A22: Not retrieved | B22: The share.gemini.google link supplied with the request could not be opened — the network egress proxy blocks that domain. No content from it is reflected here.
A24: ASSUMPTIONS ON RECORD
A25: Element mapping | B25: Fire = ignition, forging, transmutation. Water = grief, tears, fog, tides. Air = mind, signal, broadcast, breath. Earth = concrete, burial, buildings, body, archive. Assigned by this analysis; not stated in any supplied source.
A26: Vibration mapping | B26: The seven Kybalion principles plus Frequency, matched to the principle a song actually operates on rather than merely mentions. Assigned by this analysis.
A27: Heartbreak vs Empowering | B27: Follows the design document: Heartbreak sits in Intention, Empowering in Vibe, so a cathartic-not-sad pairing is expressible. Applied to the betrayal tracks.
A28: Body Jumper | B28: Tagged from author-supplied lyrics, and read as one track even though it runs Body Jumper into the Crucible Code section and an Act Four activation outro. It is the only track carrying four Vibe tags: the forensic verses (Dark, Hypnotic) and the ascension (Ethereal, Empowering) are two distinct modes, and collapsing them to three would drop a real one.
A29: Tag counts | B29: Roughly 2-3 tags per category per track. Fewer tags make a track easier to score 100% on; more tags dilute each one. Nothing in the sources fixes this number.

Sheet Track Tags
A1: Track Tags — Act III "Reclamation"
A2: Yellow columns are editable. Total Tags and all QA figures are formulas.
A4: # | B4: Track Title (public.tracks) | C4: Vibe | D4: Intention | E4: Element | F4: Theme | G4: Vibration | H4: Total Tags | I4: Evidence Basis | J4: Workbook Taxonomy (title-matched) | K4: Why These Tags
A5: 1 | B5: Welcome To The Fire | C5: Gritty, Empowering, Dark | D5: Release, Transform, Heartbreak | E5: Fire | F5: Power, Legacy, Rebirth | G5: Polarity, Frequency | H5: =IF(C5="",0,LEN(C5)-LEN(SUBSTITUTE(C5,",",""))+1)+IF(D5="",0,LEN(D5)-LEN(SUBSTITUTE(D5,",",""))+1)+IF(E5="",0,LEN(E5)-LEN(SUBSTITUTE(E5,",",""))+1)+IF(F5="",0,LEN(F5)-LEN(SUBSTITUTE(F5,",",""))+1)+IF(G5="",0,LEN(G5)-LEN(SUBSTITUTE(G5,",",""))+1) -> 12 | I5: Lyric book + workbook | J5: Initiation Through Fire | Invocation + Awakening | emberCore/ceremonial | K5: Stolen authorship and betrayal turned into ignition: "thank you for the fire / I didn't know I needed it to rise"; "I'm taking back my authorship now". Polarity for the betrayal-to-rise inversion, Frequency for "feeding her my frequency".
A6: 2 | B6: Reclamation | C6: Empowering, Gritty, Dark | D6: Release, Transform, Inspire | E6: Fire, Earth | F6: Freedom, Power, Rebirth | G6: Resonance, Polarity | H6: =IF(C6="",0,LEN(C6)-LEN(SUBSTITUTE(C6,",",""))+1)+IF(D6="",0,LEN(D6)-LEN(SUBSTITUTE(D6,",",""))+1)+IF(E6="",0,LEN(E6)-LEN(SUBSTITUTE(E6,",",""))+1)+IF(F6="",0,LEN(F6)-LEN(SUBSTITUTE(F6,",",""))+1)+IF(G6="",0,LEN(G6)-LEN(SUBSTITUTE(G6,",",""))+1) -> 13 | I6: Lyric book + workbook | J6: Power Reclamation | Resurrection + Reclamation | goldenSignal/ceremonial | K6: Wrongful confinement and return: "fifty days ticking", "this is reclamation, the day Musiq Matrix came back". Earth for the cage/box, Resonance for "my voice is the code", Polarity for "the bigger the cage, the louder the call".
A7: 3 | B7: Know Your Names | C7: Dark, Hypnotic, Gritty | D7: Focus, Protect, Awaken | E7: Air, Earth | F7: War, Power | G7: Cause & Effect, Frequency | H7: =IF(C7="",0,LEN(C7)-LEN(SUBSTITUTE(C7,",",""))+1)+IF(D7="",0,LEN(D7)-LEN(SUBSTITUTE(D7,",",""))+1)+IF(E7="",0,LEN(E7)-LEN(SUBSTITUTE(E7,",",""))+1)+IF(F7="",0,LEN(F7)-LEN(SUBSTITUTE(F7,",",""))+1)+IF(G7="",0,LEN(G7)-LEN(SUBSTITUTE(G7,",",""))+1) -> 12 | I7: Lyric book + workbook | J7: Narrative Manipulation | Exposure + Warning | buriedTruth/tectonic | K7: Cold forensic naming: "I logged the tremors before the quake was admitted", "domino logic listen, then swing". Air for "every signal hums through the wires", Earth for cold-storage archive (workbook: buriedTruth/tectonic).
A8: 4 | B8: Hold On Through The Burial | C8: Empowering, Gritty, Ethereal | D8: Heal, Inspire, Protect | E8: Earth, Water | F8: Faith, Rebirth | G8: Rhythm, Polarity | H8: =IF(C8="",0,LEN(C8)-LEN(SUBSTITUTE(C8,",",""))+1)+IF(D8="",0,LEN(D8)-LEN(SUBSTITUTE(D8,",",""))+1)+IF(E8="",0,LEN(E8)-LEN(SUBSTITUTE(E8,",",""))+1)+IF(F8="",0,LEN(F8)-LEN(SUBSTITUTE(F8,",",""))+1)+IF(G8="",0,LEN(G8)-LEN(SUBSTITUTE(G8,",",""))+1) -> 12 | I8: Lyric book + workbook | J8: Hope Against Collapse | Lament + Alignment | deepMemoryVault/ripple | K8: Endurance anthem: "the same dirt meant to bury you can raise you up again". Earth for burial/ground, Water for "the rain came down like judgment" (workbook motion: ripple). Rhythm for the night-to-dawn cycle.
A9: 5 | B9: Chosen Ones | C9: Ethereal, Hypnotic, Empowering | D9: Awaken, Inspire, Connect | E9: Air | F9: Freedom, Rebirth, Faith | G9: Frequency, Resonance, Mentalism | H9: =IF(C9="",0,LEN(C9)-LEN(SUBSTITUTE(C9,",",""))+1)+IF(D9="",0,LEN(D9)-LEN(SUBSTITUTE(D9,",",""))+1)+IF(E9="",0,LEN(E9)-LEN(SUBSTITUTE(E9,",",""))+1)+IF(F9="",0,LEN(F9)-LEN(SUBSTITUTE(F9,",",""))+1)+IF(G9="",0,LEN(G9)-LEN(SUBSTITUTE(G9,",",""))+1) -> 13 | I9: Lyric book + workbook | J9: Collective Awakening | Awakening + Alignment | goldenSignal/orbital | K9: Simulation-breach awakening: "you cracked the first encryption they installed inside your brain", "a frequency for seekers". Mentalism for the installed-encryption framing, Air for lattices of lightning/broadcast.
A10: 6 | B10: Concrete Warnings | C10: Dark, Gritty | D10: Protect, Awaken, Educate | E10: Earth, Air | F10: Loyalty, War | G10: Cause & Effect, Rhythm | H10: =IF(C10="",0,LEN(C10)-LEN(SUBSTITUTE(C10,",",""))+1)+IF(D10="",0,LEN(D10)-LEN(SUBSTITUTE(D10,",",""))+1)+IF(E10="",0,LEN(E10)-LEN(SUBSTITUTE(E10,",",""))+1)+IF(F10="",0,LEN(F10)-LEN(SUBSTITUTE(F10,",",""))+1)+IF(G10="",0,LEN(G10)-LEN(SUBSTITUTE(G10,",",""))+1) -> 11 | I10: Lyric book only | J10: — | K10: Street prophecy warning a friend about betrayers in his own ranks: "the concrete's got ears". Earth for concrete/paved-over ground, Cause & Effect and Rhythm for "history repeats, a pattern etched in pain". Lyric book only.
A11: 7 | B11: Adjacent (Reroute It) | C11: Empowering, Gritty | D11: Manifest, Educate, Focus | E11: Earth, Air | F11: Freedom, Power, Legacy | G11: Cause & Effect, Polarity | H11: =IF(C11="",0,LEN(C11)-LEN(SUBSTITUTE(C11,",",""))+1)+IF(D11="",0,LEN(D11)-LEN(SUBSTITUTE(D11,",",""))+1)+IF(E11="",0,LEN(E11)-LEN(SUBSTITUTE(E11,",",""))+1)+IF(F11="",0,LEN(F11)-LEN(SUBSTITUTE(F11,",",""))+1)+IF(G11="",0,LEN(G11)-LEN(SUBSTITUTE(G11,",",""))+1) -> 12 | I11: Lyric book + workbook | J11: Authority Restoration | Override + Invocation | redSignalStorm/ripple | K11: Gatekeeping answered by routing around it: "No seat? I'm building the table around it". Educate for the Les Paul / tape-loop history lesson; Cause & Effect for "every era repeats the same tired design".
A12: 8 | B12: Art! Official! | C12: Euphoric, Empowering, Ethereal | D12: Manifest, Educate, Inspire | E12: Air, Fire | F12: Legacy, Faith, Power | G12: Frequency, Correspondence | H12: =IF(C12="",0,LEN(C12)-LEN(SUBSTITUTE(C12,",",""))+1)+IF(D12="",0,LEN(D12)-LEN(SUBSTITUTE(D12,",",""))+1)+IF(E12="",0,LEN(E12)-LEN(SUBSTITUTE(E12,",",""))+1)+IF(F12="",0,LEN(F12)-LEN(SUBSTITUTE(F12,",",""))+1)+IF(G12="",0,LEN(G12)-LEN(SUBSTITUTE(G12,",",""))+1) -> 13 | I12: Lyric book only | J12: — | K12: AI defended as sacred craft: "I plug into the cosmos, download divine semantics", "prophetic frequencies". Correspondence for "where circuitry meets soul / divine by design". Lyric book only.
A13: 9 | B13: Thought Form | C13: Hypnotic, Ethereal | D13: Educate, Awaken, Transform | E13: Air | F13: Power, Freedom | G13: Mentalism, Correspondence, Cause & Effect | H13: =IF(C13="",0,LEN(C13)-LEN(SUBSTITUTE(C13,",",""))+1)+IF(D13="",0,LEN(D13)-LEN(SUBSTITUTE(D13,",",""))+1)+IF(E13="",0,LEN(E13)-LEN(SUBSTITUTE(E13,",",""))+1)+IF(F13="",0,LEN(F13)-LEN(SUBSTITUTE(F13,",",""))+1)+IF(G13="",0,LEN(G13)-LEN(SUBSTITUTE(G13,",",""))+1) -> 11 | I13: Lyric book + workbook | J13: Signal Transmission | Invocation + Alignment | orbitalMind/orbital | K13: The album's explicit Mentalism lecture: "The first Hermetic principle is not love... It is Mind"; "As above, so below was never just a phrase"; "You are the code beneath the cause" (workbook skin: orbitalMind).
A14: 10 | B14: Remember the Price (When You Speak the Name) | C14: Dark, Gritty, Empowering | D14: Educate, Transform, Inspire | E14: Fire, Earth | F14: Legacy, Rebirth, Power | G14: Cause & Effect, Polarity | H14: =IF(C14="",0,LEN(C14)-LEN(SUBSTITUTE(C14,",",""))+1)+IF(D14="",0,LEN(D14)-LEN(SUBSTITUTE(D14,",",""))+1)+IF(E14="",0,LEN(E14)-LEN(SUBSTITUTE(E14,",",""))+1)+IF(F14="",0,LEN(F14)-LEN(SUBSTITUTE(F14,",",""))+1)+IF(G14="",0,LEN(G14)-LEN(SUBSTITUTE(G14,",",""))+1) -> 13 | I14: Lyric book only | J14: — | K14: Shadow work priced out loud: "I audited the dark", "I metabolized hell so you could access the best", "just remember the price when you speak the name". Fire for the torch handed forward. Lyric book only.
A15: 11 | B15: Blueprint of the Divine | C15: Ethereal, Euphoric | D15: Manifest, Educate, Connect | E15: Air, Fire | F15: Faith, Legacy | G15: Correspondence, Frequency | H15: =IF(C15="",0,LEN(C15)-LEN(SUBSTITUTE(C15,",",""))+1)+IF(D15="",0,LEN(D15)-LEN(SUBSTITUTE(D15,",",""))+1)+IF(E15="",0,LEN(E15)-LEN(SUBSTITUTE(E15,",",""))+1)+IF(F15="",0,LEN(F15)-LEN(SUBSTITUTE(F15,",",""))+1)+IF(G15="",0,LEN(G15)-LEN(SUBSTITUTE(G15,",",""))+1) -> 11 | I15: Lyric book + workbook | J15: Divine Remembering | Invocation + Command Sequence | celestialGrid/orbital | K15: Four-movement prayer pattern "written before time, stitched into the design"; "how the signal travels, how the frequency finds home". Correspondence for the inherited-pattern structure (workbook: celestialGrid).
A16: 12 | B16: Flip It | C16: Empowering, Hypnotic, Euphoric | D16: Transform, Heal, Educate | E16: Air, Fire | F16: Rebirth, Freedom, Faith | G16: Polarity, Mentalism | H16: =IF(C16="",0,LEN(C16)-LEN(SUBSTITUTE(C16,",",""))+1)+IF(D16="",0,LEN(D16)-LEN(SUBSTITUTE(D16,",",""))+1)+IF(E16="",0,LEN(E16)-LEN(SUBSTITUTE(E16,",",""))+1)+IF(F16="",0,LEN(F16)-LEN(SUBSTITUTE(F16,",",""))+1)+IF(G16="",0,LEN(G16)-LEN(SUBSTITUTE(G16,",",""))+1) -> 13 | I16: Lyric book only | J16: — | K16: The album's purest Polarity track — the mechanic is literal reversal: "E-V-I-L L-I-V-E", "stressed" to "desserts", "the wound is where the gift begins", "the difference is the direction that you choose to read". Lyric book only.
... A36: 32 | B36: Body Jumper | C36: Dark, Hypnotic, Ethereal, Empowering | D36: Release, Transform, Protect | E36: Fire, Air | F36: Rebirth, Power, Freedom | G36: Polarity, Correspondence, Cause & Effect | H36: =IF(C36="",0,LEN(C36)-LEN(SUBSTITUTE(C36,",",""))+1)+IF(D36="",0,LEN(D36)-LEN(SUBSTITUTE(D36,",",""))+1)+IF(E36="",0,LEN(E36)-LEN(SUBSTITUTE(E36,",",""))+1)+IF(F36="",0,LEN(F36)-LEN(SUBSTITUTE(F36,",",""))+1)+IF(G36="",0,LEN(G36)-LEN(SUBSTITUTE(G36,",",""))+1) -> 15 | I36: Author-supplied lyrics | J36: — | K36: Composite closer that runs possession-horror into integration and hands off to Act Four. Refusal of the entity ("I am not a host—I deny access"; "I am the axis at the gate") gives Protect; the repeated "Leave every borrowed voice / name / version" and "set my old self ablaze" give Release; "I walk out burned—But redesigned" gives Transform and Rebirth. Elements are named outright in the outro — "Fire refined. Now air defines." Correspondence for "The war was never outside me—it just wore a borrowed face / Every mimic that I banished was a mirror of my case"; Polarity for "I dissolve the last distinction between hunted and the hunter"; Cause & Effect for "You don't disrupt the process—you become the documentation". Freedom for "walking through ungated doors" and the explicit end of the war; Power for melting the throne "down to the gold it was always structured under". Carries four Vibe tags — the only track that does — because the cold forensic verses (Dark, Hypnotic) and the Crucible Code ascension (Ethereal, Empowering) are genuinely two modes in one track.
A38: Tag columns C:G are the editable cells. Labels must match the Tag Dictionary sheet exactly; the database seed rejects anything else. Body Jumper is intentionally blank — no lyrics exist in any supplied source.

Sheet Tag Dictionary
A1: Tag Dictionary
A2: The closed vocabulary seeded into public.tag_dictionary. Usage counts read live from Track Tags.
A4: Category | B4: Label | C4: Glow Colour | D4: Tracks Using It | E4: Share of Album
A5: vibe | B5: Chill | C5: #FF7A1A | D5: =COUNTIF('Track Tags'!$C$5:$C$36,"*"&B5&"*") -> 2 | E5: =IFERROR(D5/COUNTA('Track Tags'!$B$5:$B$36),0) -> 0.0625
A6: vibe | B6: Euphoric | C6: #FF7A1A | D6: =COUNTIF('Track Tags'!$C$5:$C$36,"*"&B6&"*") -> 5 | E6: =IFERROR(D6/COUNTA('Track Tags'!$B$5:$B$36),0) -> 0.15625
A7: vibe | B7: Dark | C7: #FF7A1A | D7: =COUNTIF('Track Tags'!$C$5:$C$36,"*"&B7&"*") -> 19 | E7: =IFERROR(D7/COUNTA('Track Tags'!$B$5:$B$36),0) -> 0.59375
A8: vibe | B8: Dreamy | C8: #FF7A1A | D8: =COUNTIF('Track Tags'!$C$5:$C$36,"*"&B8&"*") -> 2 | E8: =IFERROR(D8/COUNTA('Track Tags'!$B$5:$B$36),0) -> 0.0625
A9: vibe | B9: Gritty | C9: #FF7A1A | D9: =COUNTIF('Track Tags'!$C$5:$C$36,"*"&B9&"*") -> 19 | E9: =IFERROR(D9/COUNTA('Track Tags'!$B$5:$B$36),0) -> 0.59375
A10: vibe | B10: Ethereal | C10: #FF7A1A | D10: =COUNTIF('Track Tags'!$C$5:$C$36,"*"&B10&"*") -> 11 | E10: =IFERROR(D10/COUNTA('Track Tags'!$B$5:$B$36),0) -> 0.34375
A11: vibe | B11: Nostalgic | C11: #FF7A1A | D11: =COUNTIF('Track Tags'!$C$5:$C$36,"*"&B11&"*") -> 8 | E11: =IFERROR(D11/COUNTA('Track Tags'!$B$5:$B$36),0) -> 0.25
A12: vibe | B12: Hypnotic | C12: #FF7A1A | D12: =COUNTIF('Track Tags'!$C$5:$C$36,"*"&B12&"*") -> 11 | E12: =IFERROR(D12/COUNTA('Track Tags'!$B$5:$B$36),0) -> 0.34375
A13: vibe | B13: Empowering | C13: #FF7A1A | D13: =COUNTIF('Track Tags'!$C$5:$C$36,"*"&B13&"*") -> 15 | E13: =IFERROR(D13/COUNTA('Track Tags'!$B$5:$B$36),0) -> 0.46875
A14: intention | B14: Manifest | C14: #1AA7FF | D14: =COUNTIF('Track Tags'!$D$5:$D$36,"*"&B14&"*") -> 5 | E14: =IFERROR(D14/COUNTA('Track Tags'!$B$5:$B$36),0) -> 0.15625
A15: intention | B15: Heal | C15: #1AA7FF | D15: =COUNTIF('Track Tags'!$D$5:$D$36,"*"&B15&"*") -> 6 | E15: =IFERROR(D15/COUNTA('Track Tags'!$B$5:$B$36),0) -> 0.1875
A16: intention | B16: Release | C16: #1AA7FF | D16: =COUNTIF('Track Tags'!$D$5:$D$36,"*"&B16&"*") -> 11 | E16: =IFERROR(D16/COUNTA('Track Tags'!$B$5:$B$36),0) -> 0.34375
A17: intention | B17: Focus | C17: #1AA7FF | D17: =COUNTIF('Track Tags'!$D$5:$D$36,"*"&B17&"*") -> 7 | E17: =IFERROR(D17/COUNTA('Track Tags'!$B$5:$B$36),0) -> 0.21875
A18: intention | B18: Awaken | C18: #1AA7FF | D18: =COUNTIF('Track Tags'!$D$5:$D$36,"*"&B18&"*") -> 8 | E18: =IFERROR(D18/COUNTA('Track Tags'!$B$5:$B$36),0) -> 0.25
A19: intention | B19: Protect | C19: #1AA7FF | D19: =COUNTIF('Track Tags'!$D$5:$D$36,"*"&B19&"*") -> 14 | E19: =IFERROR(D19/COUNTA('Track Tags'!$B$5:$B$36),0) -> 0.4375
A20: intention | B20: Transform | C20: #1AA7FF | D20: =COUNTIF('Track Tags'!$D$5:$D$36,"*"&B20&"*") -> 9 | E20: =IFERROR(D20/COUNTA('Track Tags'!$B$5:$B$36),0) -> 0.28125
A21: intention | B21: Connect | C21: #1AA7FF | D21: =COUNTIF('Track Tags'!$D$5:$D$36,"*"&B21&"*") -> 3 | E21: =IFERROR(D21/COUNTA('Track Tags'!$B$5:$B$36),0) -> 0.09375
A22: intention | B22: Heartbreak | C22: #1AA7FF | D22: =COUNTIF('Track Tags'!$D$5:$D$36,"*"&B22&"*") -> 8 | E22: =IFERROR(D22/COUNTA('Track Tags'!$B$5:$B$36),0) -> 0.25
A23: intention | B23: Educate | C23: #1AA7FF | D23: =COUNTIF('Track Tags'!$D$5:$D$36,"*"&B23&"*") -> 13 | E23: =IFERROR(D23/COUNTA('Track Tags'!$B$5:$B$36),0) -> 0.40625
A24: intention | B24: Inspire | C24: #1AA7FF | D24: =COUNTIF('Track Tags'!$D$5:$D$36,"*"&B24&"*") -> 7 | E24: =IFERROR(D24/COUNTA('Track Tags'!$B$5:$B$36),0) -> 0.21875
A25: element | B25: Fire | C25: #F5F5F5 | D25: =COUNTIF('Track Tags'!$E$5:$E$36,"*"&B25&"*") -> 16 | E25: =IFERROR(D25/COUNTA('Track Tags'!$B$5:$B$36),0) -> 0.5
A26: element | B26: Water | C26: #F5F5F5 | D26: =COUNTIF('Track Tags'!$E$5:$E$36,"*"&B26&"*") -> 9 | E26: =IFERROR(D26/COUNTA('Track Tags'!$B$5:$B$36),0) -> 0.28125
A27: element | B27: Air | C27: #F5F5F5 | D27: =COUNTIF('Track Tags'!$E$5:$E$36,"*"&B27&"*") -> 15 | E27: =IFERROR(D27/COUNTA('Track Tags'!$B$5:$B$36),0) -> 0.46875
A28: element | B28: Earth | C28: #F5F5F5 | D28: =COUNTIF('Track Tags'!$E$5:$E$36,"*"&B28&"*") -> 19 | E28: =IFERROR(D28/COUNTA('Track Tags'!$B$5:$B$36),0) -> 0.59375
A29: theme | B29: Rebirth | C29: #B14AFF | D29: =COUNTIF('Track Tags'!$F$5:$F$36,"*"&B29&"*") -> 13 | E29: =IFERROR(D29/COUNTA('Track Tags'!$B$5:$B$36),0) -> 0.40625
A30: theme | B30: Power | C30: #B14AFF | D30: =COUNTIF('Track Tags'!$F$5:$F$36,"*"&B30&"*") -> 17 | E30: =IFERROR(D30/COUNTA('Track Tags'!$B$5:$B$36),0) -> 0.53125
A31: theme | B31: Legacy | C31: #B14AFF | D31: =COUNTIF('Track Tags'!$F$5:$F$36,"*"&B31&"*") -> 11 | E31: =IFERROR(D31/COUNTA('Track Tags'!$B$5:$B$36),0) -> 0.34375
A32: theme | B32: Faith | C32: #B14AFF | D32: =COUNTIF('Track Tags'!$F$5:$F$36,"*"&B32&"*") -> 11 | E32: =IFERROR(D32/COUNTA('Track Tags'!$B$5:$B$36),0) -> 0.34375
A33: theme | B33: Love | C33: #B14AFF | D33: =COUNTIF('Track Tags'!$F$5:$F$36,"*"&B33&"*") -> 7 | E33: =IFERROR(D33/COUNTA('Track Tags'!$B$5:$B$36),0) -> 0.21875
A34: theme | B34: War | C34: #B14AFF | D34: =COUNTIF('Track Tags'!$F$5:$F$36,"*"&B34&"*") -> 11 | E34: =IFERROR(D34/COUNTA('Track Tags'!$B$5:$B$36),0) -> 0.34375
A35: theme | B35: Freedom | C35: #B14AFF | D35: =COUNTIF('Track Tags'!$F$5:$F$36,"*"&B35&"*") -> 13 | E35: =IFERROR(D35/COUNTA('Track Tags'!$B$5:$B$36),0) -> 0.40625
A36: theme | B36: Loyalty | C36: #B14AFF | D36: =COUNTIF('Track Tags'!$F$5:$F$36,"*"&B36&"*") -> 5 | E36: =IFERROR(D36/COUNTA('Track Tags'!$B$5:$B$36),0) -> 0.15625
A37: vibration | B37: Mentalism | C37: #3CFF6E | D37: =COUNTIF('Track Tags'!$G$5:$G$36,"*"&B37&"*") -> 7 | E37: =IFERROR(D37/COUNTA('Track Tags'!$B$5:$B$36),0) -> 0.21875
A38: vibration | B38: Correspondence | C38: #3CFF6E | D38: =COUNTIF('Track Tags'!$G$5:$G$36,"*"&B38&"*") -> 6 | E38: =IFERROR(D38/COUNTA('Track Tags'!$B$5:$B$36),0) -> 0.1875
A39: vibration | B39: Polarity | C39: #3CFF6E | D39: =COUNTIF('Track Tags'!$G$5:$G$36,"*"&B39&"*") -> 15 | E39: =IFERROR(D39/COUNTA('Track Tags'!$B$5:$B$36),0) -> 0.46875
A40: vibration | B40: Rhythm | C40: #3CFF6E | D40: =COUNTIF('Track Tags'!$G$5:$G$36,"*"&B40&"*") -> 7 | E40: =IFERROR(D40/COUNTA('Track Tags'!$B$5:$B$36),0) -> 0.21875
A41: vibration | B41: Cause & Effect | C41: #3CFF6E | D41: =COUNTIF('Track Tags'!$G$5:$G$36,"*"&B41&"*") -> 17 | E41: =IFERROR(D41/COUNTA('Track Tags'!$B$5:$B$36),0) -> 0.53125
...

Sheet Source Reconciliation
A1: Source Reconciliation
A2: Why the tags come from the lyric book and UPDATED.xlsx, and why CORRECTED2.xlsm was set aside.
A4: FINDING
A5: What happened | B5: CORRECTED2.xlsm carries the correct 32-track roster and the correct titles, but its taxonomy columns (Core Theme, Signal Types, Lyric Mode, Visual Skin, Motion Style, Particles, Events) were not re-mapped when the roster was re-ordered. Each taxonomy row still sits where it sat in the older UPDATED.xlsx ordering, so it now describes a different song than the title beside it.
A6: How it was confirmed | B6: Row by row against UPDATED.xlsx. Three independent sources — the lyric book, CORRECTED2.xlsm and the live public.tracks roster — agree on the 32 titles and their order, which isolates the taxonomy block as the thing that moved.
A7: Worked example | B7: CORRECTED2 row 19 "Through The Fog" carries Truth Broadcast / Confession + Transmutation / crucibleEngine. That is the Blood Without Stains taxonomy in UPDATED.xlsx. Through The Fog is a fog-and-tides lament; a crucible treatment does not describe it.
A8: Second example | B8: CORRECTED2 row 21 "Misguided Priorities" carries Spiritual War / Revolt + Transmutation, which belongs to Seer Broke Chains. Misguided Priorities is a grief song; UPDATED gives it Grief Processing / liquidMirror when joined by title.
A9: Decision | B9: Tags derive from the lyric book, corroborated by UPDATED.xlsx joined BY TITLE. CORRECTED2 contributes its roster and titles only, which is what it demonstrably gets right.
A10: Impact if ignored | B10: Had CORRECTED2 taxonomy been trusted, roughly two thirds of the album would carry another song's mood, element and theme, and every alchemizr match would be wrong in a way no user could diagnose.
A12: OTHER SOURCE NOTES
A13: Titles | B13: Tag rows key on the exact public.tracks strings, including the curly apostrophe in "The Witness Don't Talk" and the two-word "Body Jumper". The seed migration fails loudly if any title stops matching.
A14: Media & Lyrics sheets | B14: Both workbooks ship a "Media & Lyrics" sheet with Audio URL, Artwork URL and Lyrics columns that are empty in every row. Nothing was drawn from them.
A15: Gemini link | B15: The share.gemini.google URL supplied with the request is blocked by this environment's network egress proxy and could not be read. If it contains tag decisions, they are not reflected here.

Sheet Coverage QA
A1: Coverage QA
A2: Every figure is a formula reading the Track Tags sheet.
A4: Metric | B4: Value | C4: Note
A5: Tracks in the album | B5: =COUNTA('Track Tags'!$B$5:$B$36) -> 32 | C5: Rows on the Track Tags sheet.
A6: Tracks tagged | B6: =COUNTIF('Track Tags'!$H$5:$H$36,">0") -> 32 | C6: At least one tag in any category.
A7: Tracks untagged | B7: =COUNTIF('Track Tags'!$H$5:$H$36,0) -> 0 | C7: Every track now carries tags.
A8: Total tag assignments | B8: =SUM('Track Tags'!$H$5:$H$36) -> 397 | C8: Across all five categories.
A9: Average tags per tagged track | B9: =IFERROR(B8/B6,0) -> 12.40625 | C9: Total assignments divided by tagged tracks.
A10: Corroborated by workbook | B10: =COUNTIF('Track Tags'!$I$5:$I$36,"Lyric book + workbook") -> 21 | C10: Lyric evidence plus a title-matched taxonomy row.
A11: Lyric book only | B11: =COUNTIF('Track Tags'!$I$5:$I$36,"Lyric book only") -> 10 | C11: No taxonomy row survives the title join for these.
A12: Author-supplied lyrics | B12: =COUNTIF('Track Tags'!$I$5:$I$36,"Author-supplied lyrics") -> 1 | C12: Body Jumper — lyrics provided directly, absent from the master lyric book.
A13: Vocabulary labels defined | B13: =COUNTA('Tag Dictionary'!$B$5:$B$44) -> 40 | C13: Closed vocabulary size.
A14: Vocabulary labels in use | B14: =COUNTIF('Tag Dictionary'!$D$5:$D$44,">0") -> 40 | C14: Every label is used at least once, so no tag is dead weight in the rain field.
A16: Tags per category
A17: Vibe | B17: =SUMPRODUCT((LEN('Track Tags'!$C$5:$C$36)-LEN(SUBSTITUTE('Track Tags'!$C$5:$C$36,",","")))+((LEN('Track Tags'!$C$5:$C$36)>0)*1)) -> 92 | C17: Assignments in the Vibe column.
A18: Intention | B18: =SUMPRODUCT((LEN('Track Tags'!$D$5:$D$36)-LEN(SUBSTITUTE('Track Tags'!$D$5:$D$36,",","")))+((LEN('Track Tags'!$D$5:$D$36)>0)*1)) -> 91 | C18: Assignments in the Intention column.
A19: Element | B19: =SUMPRODUCT((LEN('Track Tags'!$E$5:$E$36)-LEN(SUBSTITUTE('Track Tags'!$E$5:$E$36,",","")))+((LEN('Track Tags'!$E$5:$E$36)>0)*1)) -> 59 | C19: Assignments in the Element column.
A20: Theme | B20: =SUMPRODUCT((LEN('Track Tags'!$F$5:$F$36)-LEN(SUBSTITUTE('Track Tags'!$F$5:$F$36,",","")))+((LEN('Track Tags'!$F$5:$F$36)>0)*1)) -> 88 | C20: Assignments in the Theme column.
A21: Vibration | B21: =SUMPRODUCT((LEN('Track Tags'!$G$5:$G$36)-LEN(SUBSTITUTE('Track Tags'!$G$5:$G$36,",","")))+((LEN('Track Tags'!$G$5:$G$36)>0)*1)) -> 67 | C21: Assignments in the Vibration column.
